<?xml version='1.0'?>

<robot name="my_robot" xmlns:xacro="http://www.ros.org/wiki/xacro">
    <xacro:include filename="$(find my_robot)/urdf/my_robot.gazebo"/>    
    <link name="robot_footprint"/>

    <joint name="robot_footprint_joint" type="fixed">
        <origin xyz="0 0 0" rpy="0 0 0" />
        <parent link="robot_footprint"/>
        <child link="chassis"/>
    </joint>
    
    <link name="chassis">
        <pose> 0 0 0 0 0 0</pose>
        <inertial>
            <mass value="8.0"/>
            <origin xyz="0 0 0" rpy="0 0 0"/>
            <inertia ixx="0.3" 
                     iyy="0.3" 
                     izz="0.1" 
                     ixy="0.0" ixz="0.0" iyz="0.0" 
                     />
         </inertial>

        <collision name="chassis_collision">
            <origin xyz="0 0 0" rpy="0 0 0"/>
            <geometry>
                <box size='0.5 0.3 0.15'/>
            </geometry>
        </collision>

        <visual name="chassis_visual">
            <origin xyz="0 0 0" rpy="0 0 0"/>
            <geometry>
                <box size='0.5 0.3 0.15'/>
            </geometry>
        </visual>
    </link>

    <gazebo reference="chassis">
        <material>Gazebo/Yellow</material>
    </gazebo>

    <!-- Head
    \\\\\\\\\\\\\\\\\\\\\\\\\\\\\\\\\\\\\\\\\\\\\\\\\-->

    <link name="head">
        <pose> 0 0 0 0 0 0</pose>
        <inertial>
            <mass value="0.2"/>
            <origin xyz="0 0 0" rpy="0 0 0"/>
            <inertia ixx="0.1" 
                     iyy="0.1" 
                     izz="0.1" 
                     ixy="0.0" ixz="0.0" iyz="0.0" 
                     />
         </inertial>

        <collision >
            <origin xyz="0 0 0" rpy="0 0 0"/>
            <geometry>
                <box size='0.3 0.25 0.25'/>
            </geometry>
        </collision>

        <visual >
            <origin xyz="0 0 0" rpy="0 0 0"/>
            <geometry>
                <box size='0.25 0.25 0.25'/>
            </geometry>
        </visual>
    </link>

    <gazebo reference="head">
        <material>Gazebo/Yellow</material>
    </gazebo>

    
    <joint name="head_joint" type="fixed">
        <origin xyz='0 0 0.2' rpy="0 0 0"/>
        <child link="head"/>
        <parent link="chassis"/>
        <axis xyz="0 0 1" rpy="0 0 0"/>
        <limit effort="1000" velocity="1000"/>
        <dynamics damping="0.1" friction="0.1"/>
    </joint>

    <!-- Eyes
    \\\\\\\\\\\\\\\\\\\\\\\\\\\\\\\\\\\\\\\\\\\\\\\\\-->
    <link name="left_eye">
        <collision>
            <origin xyz="0 0 0" rpy="0 1.5707 0"/>
            <geometry>
                <cylinder radius="0.03" length="0.01"/>
            </geometry>
        </collision>

        <inertial>
            <mass value="0.1"/>
            <origin xyz="0 0 0" rpy="0 1.5707 0"/>
            <inertia
                ixx='0.1'
                iyy='0.1'
                izz='0.1' 
                ixy="0" ixz="0" iyz="0"
                />
        </inertial>

        <visual>
            <origin xyz="0 0 0" rpy="0 1.5707 0"/>
            <geometry>
                <cylinder radius="0.03" length="0.01"/>
            </geometry>
        </visual>
    </link>

    <link name="right_eye">
        <collision>
            <origin xyz="0 0 0" rpy="0 1.5707 0"/>
            <geometry>
                <cylinder radius="0.03" length="0.01"/>
            </geometry>
        </collision>

        <inertial>
            <mass value="0.1"/>
            <origin xyz="0 0 0" rpy="0 1.5707 0"/>
            <inertia
                ixx='0.1'
                iyy='0.1'
                izz='0.1' 
                ixy="0" ixz="0" iyz="0"
                />
        </inertial>

        <visual>
            <origin xyz="0 0 0" rpy="0 1.5707 0"/>
            <geometry>
                <cylinder radius="0.03" length="0.01"/>
            </geometry>
        </visual>
    </link>

    <gazebo reference="left_eye">
        <material>Gazebo/White</material>
    </gazebo>
    <gazebo reference="right_eye">
        <material>Gazebo/White</material>
    </gazebo>

    <joint name="left_eye_joint" type="fixed">
        <origin xyz='0.13 0.06 0.06' rpy="0 0 0"/>
        <child link="left_eye"/>
        <parent link="head"/>
        <axis xyz="0 0 1" rpy="0 0 0"/>
        <limit effort="1000" velocity="1000"/>
        <dynamics damping="0.1" friction="0.1"/>
    </joint>

    <joint name="right_eye_joint" type="fixed">
        <origin xyz='0.13 -0.06 0.06' rpy="0 0 0"/>
        <child link="right_eye"/>
        <parent link="head"/>
        <axis xyz="0 0 1" rpy="0 0 0"/>
        <limit effort="1000" velocity="1000"/>
        <dynamics damping="0.1" friction="0.1"/>
    </joint>

    <!-- Pupils
    \\\\\\\\\\\\\\\\\\\\\\\\\\\\\\\\\\\\\\\\\\\\\\\\\-->
    <link name="left_pupil">
        <collision>
            <origin xyz="0 0 0" rpy="0 1.5707 0"/>
            <geometry>
                <cylinder radius="0.01" length="0.005"/>
            </geometry>
        </collision>

        <inertial>
            <mass value="0.1"/>
            <origin xyz="0 0 0" rpy="0 1.5707 0"/>
            <inertia
                ixx='0.1'
                iyy='0.1'
                izz='0.1' 
                ixy="0" ixz="0" iyz="0"
                />
        </inertial>

        <visual>
            <origin xyz="0 0 0" rpy="0 1.5707 0"/>
            <geometry>
                <cylinder radius="0.01" length="0.005"/>
            </geometry>
        </visual>
    </link>

    <link name="right_pupil">
        <collision>
            <origin xyz="0 0 0" rpy="0 1.5707 0"/>
            <geometry>
                <cylinder radius="0.01" length="0.005"/>
            </geometry>
        </collision>

        <inertial>
            <mass value="0.1"/>
            <origin xyz="0 0 0" rpy="0 1.5707 0"/>
            <inertia
                ixx='0.1'
                iyy='0.1'
                izz='0.1' 
                ixy="0" ixz="0" iyz="0"
                />
        </inertial>

        <visual>
            <origin xyz="0 0 0" rpy="0 1.5707 0"/>
            <geometry>
                <cylinder radius="0.01" length="0.005"/>
            </geometry>
        </visual>
    </link>

    <gazebo reference="left_pupil">
        <material>Gazebo/Black</material>
    </gazebo>

    <gazebo reference="right_pupil">
        <material>Gazebo/Black</material>
    </gazebo>

    <joint name="left_pupil_joint" type="fixed">
        <origin xyz='0.0075 0 0.01' rpy="0 0 0"/>
        <child link="left_pupil"/>
        <parent link="left_eye"/>
        <axis xyz="0 0 1" rpy="0 0 0"/>
        <limit effort="1000" velocity="1000"/>
        <dynamics damping="0.1" friction="0.1"/>
    </joint>

    <joint name="right_pupil_joint" type="fixed">
        <origin xyz='0.0075 0 0.01' rpy="0 0 0"/>
        <child link="right_pupil"/>
        <parent link="right_eye"/>
        <axis xyz="0 0 1" rpy="0 0 0"/>
        <limit effort="1000" velocity="1000"/>
        <dynamics damping="0.1" friction="0.1"/>
    </joint>

    <!-- Eyebrows
    \\\\\\\\\\\\\\\\\\\\\\\\\\\\\\\\\\\\\\\\\\\\\\\\\-->
    <link name="left_eyebrow">
        <pose> 0 0 0 0 0 0</pose>
        <inertial>
            <mass value="0.1"/>
            <origin xyz="0 0 0" rpy="-0.3 0 0"/>
            <inertia ixx="0.1" 
                     iyy="0.1" 
                     izz="0.1" 
                     ixy="0.0" ixz="0.0" iyz="0.0" 
                     />
         </inertial>

        <collision >
            <origin xyz="0 0 0" rpy="-0.3 0 0"/>
            <geometry>
                <box size='0.02 0.08 0.01'/>
            </geometry>
        </collision>

        <visual >
            <origin xyz="0 0 0" rpy="-0.3 0 0"/>
            <geometry>
                <box size='0.02 0.08 0.01'/>
            </geometry>
        </visual>
    </link>

    <link name="right_eyebrow">
        <pose> 0 0 0 0 0 0</pose>
        <inertial>
            <mass value="0.1"/>
            <origin xyz="0 0 0" rpy="0.3 0 0"/>
            <inertia ixx="0.1" 
                     iyy="0.1" 
                     izz="0.1" 
                     ixy="0.0" ixz="0.0" iyz="0.0" 
                     />
         </inertial>

        <collision >
            <origin xyz="0 0 0" rpy="0.3 0 0"/>
            <geometry>
                <box size='0.02 0.08 0.01'/>
            </geometry>
        </collision>

        <visual >
            <origin xyz="0 0 0" rpy="0.3 0 0"/>
            <geometry>
                <box size='0.02 0.08 0.01'/>
            </geometry>
        </visual>
    </link>

    <gazebo reference="left_eyebrow">
        <material>Gazebo/Black</material>
    </gazebo>

    <gazebo reference="right_eyebrow">
        <material>Gazebo/Black</material>
    </gazebo>

    <joint name="left_eyebrow_joint" type="fixed">
        <origin xyz='0.135 0.07 0.1' rpy="0 0 0"/>
        <child link="left_eyebrow"/>
        <parent link="head"/>
        <axis xyz="0 0 1" rpy="0 0 0"/>
        <limit effort="1000" velocity="1000"/>
        <dynamics damping="0.1" friction="0.1"/>
    </joint>

    <joint name="right_eyebrow_joint" type="fixed">
        <origin xyz='0.135 -0.07 0.1' rpy="0 0 0"/>
        <child link="right_eyebrow"/>
        <parent link="head"/>
        <axis xyz="0 0 1" rpy="0 0 0"/>
        <limit effort="1000" velocity="1000"/>
        <dynamics damping="0.1" friction="0.1"/>
    </joint>

    <!-- SENSORS
    \\\\\\\\\\\\\\\\\\\\\\\\\\\\\\\\\\\\\\\\\\\\\\\\\-->

    <link name='camera'>
        <pose>0 0 0 0 0 0</pose>

        <inertial>
        <mass value="0.1"/>
        <origin xyz="0.05 0.05 0.05" rpy=" 0 0 0"/>
         <inertia
             ixx="1e-6" ixy="0" ixz="0"
             iyy="1e-6" iyz="0"
              izz="1e-6"
        />
        </inertial>

        <collision>
         <origin xyz="0 0 0" rpy=" 0 0 0"/> 
        <geometry>
         <box size=".03 .03 .03"/>
         </geometry>
        </collision>

        <visual>
         <origin xyz="0 0 0" rpy=" 0 0 0"/>
          <geometry>
           <box size=".03 .03 .03"/>
          </geometry>
        </visual>
    </link>

    <gazebo reference="camera">
        <material>Gazebo/Blue</material>
    </gazebo>

    <joint type="fixed" name="camera_joint">
        <origin xyz="0.14 0 0" rpy="0 0 0"/>
        <child link="camera"/>
        <parent link="head"/>
        <axis xyz="0 1 0" rpy="0 0 0"/>
    </joint>

    <link name='hokuyo'>
        <pose>0 0 0 0 0 0</pose>

        <inertial>
            <mass value="1e-5"/>
            <origin xyz="0 0 0" rpy="0 0 0"/>
            <inertia
                ixx="1e-6" ixy="0" ixz="0"
                iyy="1e-6" iyz="0"
                izz="1e-6"
            />
        </inertial>

        <collision>
            <origin xyz="0 0 0" rpy=" 0 0 0"/> 
            <geometry>
                <box size=".1 .1 .1"/>
            </geometry>
        </collision>

        <visual >
            <origin xyz="0 0 0" rpy=" 0 0 0"/>
            <geometry>
                <mesh filename="package://my_robot/meshes/hokuyo.dae"/>
            </geometry>
        </visual>
    </link>

    <gazebo reference="hokuyo">
        <material>Gazebo/Blue</material>
    </gazebo>

    <joint type="fixed" name="hokuyo_joint">
        <origin xyz="0 0 0.15" rpy="0 0 0"/>
        <child link="hokuyo"/>
        <parent link="head"/>
        <axis xyz="0 1 0" rpy="0 0 0"/>
    </joint>

    <!-- FRONT WHEELS \\\\\\\\\\\\\\\\\\\\\\\\\\\\\\\\\\\\\\\\\\\\\\\\\-->
    <link name="front_left_wheel">
        <collision>
            <origin xyz="0 0 0" rpy="0 1.5707 1.5707"/>
            <geometry>
                <cylinder radius="0.1" length="0.03"/>
            </geometry>
        </collision>

        <inertial>
            <mass value="1.0"/>
            <origin xyz="0 0 0" rpy="0 1.5707 1.5707"/>
            <inertia
                ixx='0.1'
                iyy='0.1'
                izz='0.2' 
                ixy="0" ixz="0" iyz="0"
                />
        </inertial>

        <visual>
            <origin xyz="0 0 0" rpy="0 1.5707 1.5707"/>
            <geometry>
                <cylinder radius="0.1" length="0.03"/>
            </geometry>
        </visual>
    </link>
  
    <link name="front_right_wheel">
        <collision>
            <origin xyz="0 0 0" rpy="0 1.5707 1.5707"/>
            <geometry>
                <cylinder radius="0.1" length="0.03"/>
            </geometry>
        </collision>

        <inertial>
            <mass value="1.0"/>
            <origin xyz="0 0 0" rpy="0 1.5707 1.5707"/>
            <inertia
                ixx='0.1'
                iyy='0.1'
                izz='0.2' 
                ixy="0" ixz="0" iyz="0"
                />
        </inertial>

        <visual>
            <origin xyz="0 0 0" rpy="0 1.5707 1.5707"/>
            <geometry>
                <cylinder radius="0.1" length="0.03"/>
            </geometry>
        </visual>
    </link>


    <!-- Strut dims are derived from the dims of the wheel they carry -->
    <link name="front_left_strut">
        <collision>
            <origin xyz="0 0 0" rpy="0 0 0"/>
            <geometry>
                <box size='0.03 0.03 0.1'/>
            </geometry>
        </collision>

        <inertial> 
            <mass value="0.2"/>
            <origin xyz="0 0 0" rpy="0 0 0"/>
            <inertia 
                     ixx="0.1" 
                     iyy="0.1" 
                     izz="0.1" 
                     ixy="0.0" ixz="0.0" iyz="0.0" 
            />
        </inertial>

        <visual>
            <origin xyz="0 0 0" rpy="0 0 0"/>
            <geometry>
                <box size='0.03 0.03 0.1'/>
            </geometry>
        </visual>
    </link>

    <link name="front_right_strut">
        <collision>
            <origin xyz="0 0 0" rpy="0 0 0"/>
            <geometry>
                <box size='0.03 0.03 0.1'/>
            </geometry>
        </collision>

        <inertial> 
            <mass value="0.2"/>
            <origin xyz="0 0 0" rpy="0 0 0"/>
            <inertia 
                     ixx="0.1" 
                     iyy="0.1" 
                     izz="0.1" 
                     ixy="0.0" ixz="0.0" iyz="0.0" 
                     />
        </inertial>

        <visual>
            <origin xyz="0 0 0" rpy="0 0 0"/>
            <geometry>
                <box size='0.03 0.03 0.1'/>
            </geometry>
        </visual>
    </link>

    <gazebo reference="front_left_strut">
        <material>Gazebo/DarkGrey</material>
    </gazebo>
    <gazebo reference="front_right_strut">
        <material>Gazebo/DarkGrey</material>
    </gazebo>
    <gazebo reference="front_left_wheel">
        <material>Gazebo/Black</material>
    </gazebo>
    <gazebo reference="front_right_wheel">
        <material>Gazebo/Black</material>
    </gazebo>


    <joint name="front_left_wheel_bearing" type="continuous">
        <origin xyz="0 0.032 0" rpy="0 0 0"/>
        <child link="front_left_wheel"/>
        <parent link="front_left_strut"/>
        <axis xyz="0 1 0" rpy="0 0 0"/>
        <limit effort="10000" velocity="1000"/>
        <dynamics damping="0.005" friction="0.005"/>
    </joint>
  
    <joint name="front_left_steer_bearing" type="continuous">
        <origin xyz='0.175 0.18 0' rpy="0 0 0"/>
        <child link="front_left_strut"/>
        <parent link="chassis"/>
        <axis xyz="0 0 1" rpy="0 0 0"/>
        <limit effort="1000" velocity="1000"/>
        <dynamics damping="0.1" friction="0.1"/>
    </joint>

     <joint name="front_right_wheel_bearing" type="continuous">
        <origin xyz="0 -0.032 0" rpy="0 0 0"/>
        <child link="front_right_wheel"/>
        <parent link="front_right_strut"/>
        <axis xyz="0 1 0" rpy="0 0 0"/>
        <limit effort="10000" velocity="1000"/>
        <dynamics damping="0.005" friction="0.005"/>
    </joint>
  
    <joint name="front_right_steer_bearing" type="continuous">
        <origin xyz='0.175 -0.18 0' rpy="0 0 0"/>
        <child link="front_right_strut"/>
        <parent link="chassis"/>
        <axis xyz="0 0 1" rpy="0 0 0"/>
        <limit effort="1000" velocity="1000"/>
        <dynamics damping="0.1" friction="0.1"/>
    </joint>

    <!-- REAR WHEELS \\\\\\\\\\\\\\\\\\\\\\\\\\\\\\\\\\\\\\\\\\\\\\\\\-->
    <link name="rear_left_wheel">
        <collision>
            <origin xyz="0 0 0" rpy="0 1.5707 1.5707"/>
            <geometry>
                <cylinder radius="0.1" length="0.03"/>
            </geometry>
        </collision>

        <inertial>
            <mass value="1.0"/>
            <origin xyz="0 0 0" rpy="0 1.5707 1.5707"/>
            <inertia
                ixx='0.1'
                iyy='0.1'
                izz='0.2' 
                ixy="0" ixz="0" iyz="0"
                />
        </inertial>

        <visual>
            <origin xyz="0 0 0" rpy="0 1.5707 1.5707"/>
            <geometry>
                <cylinder radius="0.1" length="0.03"/>
            </geometry>
        </visual>
    </link>
  
    <link name="rear_right_wheel">
        <collision>
            <origin xyz="0 0 0" rpy="0 1.5707 1.5707"/>
            <geometry>
                <cylinder radius="0.1" length="0.03"/>
            </geometry>
        </collision>

        <inertial>
            <mass value="1.0"/>
            <origin xyz="0 0 0" rpy="0 1.5707 1.5707"/>
            <inertia
                ixx='0.1'
                iyy='0.1'
                izz='0.2' 
                ixy="0" ixz="0" iyz="0"
                />
        </inertial>

        <visual>
            <origin xyz="0 0 0" rpy="0 1.5707 1.5707"/>
            <geometry>
                <cylinder radius="0.1" length="0.03"/>
            </geometry>
        </visual>
    </link>


    <!-- Strut dims are derived from the dims of the wheel they carry -->
    <link name="rear_left_strut">
        <collision>
            <origin xyz="0 0 0" rpy="0 0 0"/>
            <geometry>
                <box size='0.03 0.03 0.1'/>
            </geometry>
        </collision>

        <inertial> 
            <mass value="0.2"/>
            <origin xyz="0 0 0" rpy="0 0 0"/>
            <inertia 
                     ixx="0.1" 
                     iyy="0.1" 
                     izz="0.1" 
                     ixy="0.0" ixz="0.0" iyz="0.0" 
                     />
        </inertial>

        <visual>
            <origin xyz="0 0 0" rpy="0 0 0"/>
            <geometry>
                <box size='0.03 0.03 0.1'/>
            </geometry>
        </visual>
    </link>

    <link name="rear_right_strut">
        <collision>
            <origin xyz="0 0 0" rpy="0 0 0"/>
            <geometry>
                <box size='0.03 0.03 0.1'/>
            </geometry>
        </collision>

        <inertial> 
            <mass value="2.0"/>
            <origin xyz="0 0 0" rpy="0 0 0"/>
            <inertia 
                     ixx="0.1" 
                     iyy="0.1" 
                     izz="0.1" 
                     ixy="0.0" ixz="0.0" iyz="0.0" 
                     />
        </inertial>

        <visual>
            <origin xyz="0 0 0" rpy="0 0 0"/>
            <geometry>
                <box size='0.03 0.03 0.1'/>
            </geometry>
        </visual>
    </link>

    <gazebo reference="rear_left_strut">
        <material>Gazebo/DarkGrey</material>
    </gazebo>
    <gazebo reference="rear_right_strut">
        <material>Gazebo/DarkGrey</material>
    </gazebo>
    <gazebo reference="rear_left_wheel">
        <material>Gazebo/Black</material>
    </gazebo>
    <gazebo reference="rear_right_wheel">
        <material>Gazebo/Black</material>
    </gazebo>


    <joint name="rear_left_wheel_bearing" type="continuous">
        <origin xyz="0 0.032 0" rpy="0 0 0"/>
        <child link="rear_left_wheel"/>
        <parent link="rear_left_strut"/>
        <axis xyz="0 1 0" rpy="0 0 0"/>
        <limit effort="10000" velocity="1000"/>
        <dynamics damping="0.005" friction="0.005"/>
    </joint>
  
    <joint name="rear_left_steer_bearing" type="fixed">
        <origin xyz='-0.175 0.18 0' rpy="0 0 0"/>
        <child link="rear_left_strut"/>
        <parent link="chassis"/>
        <axis xyz="0 0 1" rpy="0 0 0"/>
        <limit effort="1000" velocity="1000"/>
        <dynamics damping="0.1" friction="0.1"/>
    </joint>

    <joint name="rear_right_wheel_bearing" type="continuous">
        <origin xyz="0 -0.032 0" rpy="0 0 0"/>
        <child link="rear_right_wheel"/>
        <parent link="rear_right_strut"/>
        <axis xyz="0 1 0" rpy="0 0 0"/>
        <limit effort="10000" velocity="1000"/>
        <dynamics damping="0.005" friction="0.005"/>
    </joint>
  
    <joint name="rear_right_steer_bearing" type="fixed">
        <origin xyz='-0.175 -0.18 0' rpy="0 0 0"/>
        <child link="rear_right_strut"/>
        <parent link="chassis"/>
        <axis xyz="0 0 1" rpy="0 0 0"/>
        <limit effort="1000" velocity="1000"/>
        <dynamics damping="0.1" friction="0.1"/>
    </joint>


</robot>

